<?xml version="1.0"?>
<robot name="nexus_4wd_mecanum" xmlns:xacro="http://ros.org/wiki/xacro">

  <xacro:property name="PI" value="3.1415926535897931" />

  <xacro:property name="wheel_radius" value="0.050" />
  <xacro:property name="wheel_width" value="0.0505" />

  <material name="yellow"><color rgba="0.8 0.8 0.0 1.0" /></material>
  <material name="black"><color rgba="0.15 0.15 0.15 1.0" /></material>
  <material name="dark_grey"><color rgba="0.2 0.2 0.2 1.0" /></material>
  <material name="light_grey"><color rgba="0.4 0.4 0.4 1.0" /></material>

  <link name="base_footprint"></link>

  <joint name="base_link_joint" type="fixed">
    <origin xyz="0 0 0.05" rpy="0 0 0" />
    <parent link="base_footprint"/>
    <child link="base_link" />
  </joint>

  <link name="base_link">
    <visual>
      <origin xyz="0 0 0" rpy="0 0 0" />
      <geometry>
        <mesh filename="package://nexus_4wd_mecanum_description/meshes/nexus_base_link.STL" scale="0.001 0.001 0.001"/>
      </geometry>
      <material name="yellow" />
    </visual>
    <collision>
      <origin xyz="0 0 0"/>
      <geometry>
        <mesh filename="package://nexus_4wd_mecanum_description/meshes/nexus_base_link_collision.STL" scale="0.001 0.001 0.001"/>
      </geometry>
    </collision>
    <inertial>
      <!-- Inertia from CAD model, filled box assumption -->
      <origin xyz="-0.01103 0 0.002" rpy="0 0 0"/>
      <mass value="2.844"/>
      <inertia
        ixx="0.018819942" ixy="0" ixz="-0.000101519"
        iyy="0.057333716" iyz="0"
        izz="0.074201740"/>
    </inertial>
  </link>

  <joint name="upper_left_wheel_shaft_joint" type="fixed">
    <origin xyz="0.150 0.108 0.0" rpy="0 0 0" />
    <parent link="base_link"/>
    <child link="upper_left_wheel_shaft" />
  </joint>

  <link name="upper_left_wheel_shaft">
    <visual>
      <origin xyz="0 0 0" rpy="0 0 0" />
      <geometry>
        <mesh filename="package://nexus_4wd_mecanum_description/meshes/wheel_shaft.STL" scale="0.001 0.001 0.001"/>
      </geometry>
      <material name="black" />
    </visual>
    <collision>
      <origin xyz="0 0 0"/>
      <geometry>
        <mesh filename="package://nexus_4wd_mecanum_description/meshes/wheel_shaft.STL" scale="0.001 0.001 0.001"/>
      </geometry>
    </collision>
    <inertial>
      <origin xyz="0 0.01221 0" rpy="0 0 0"/>
      <mass value="0.055"/>
      <inertia
        ixx="0.000021370" ixy="0" ixz="0"
        iyy="0.000009966" iyz="0"
        izz="0.000021370"/>
    </inertial>
  </link>

  <joint name="lower_left_wheel_shaft_joint" type="fixed">
    <origin xyz="-0.150 0.108 0.0" rpy="0 0 0" />
    <parent link="base_link"/>
    <child link="lower_left_wheel_shaft" />
  </joint>

  <link name="lower_left_wheel_shaft">
    <visual>
      <origin xyz="0 0 0" rpy="0 0 0" />
      <geometry>
        <mesh filename="package://nexus_4wd_mecanum_description/meshes/wheel_shaft.STL" scale="0.001 0.001 0.001"/>
      </geometry>
      <material name="black" />
    </visual>
    <collision>
      <origin xyz="0 0 0"/>
      <geometry>
        <mesh filename="package://nexus_4wd_mecanum_description/meshes/wheel_shaft.STL" scale="0.001 0.001 0.001"/>
      </geometry>
    </collision>
    <inertial>
      <origin xyz="0 0.01221 0" rpy="0 0 0"/>
      <mass value="0.055"/>
      <inertia
        ixx="0.000021370" ixy="0" ixz="0"
        iyy="0.000009966" iyz="0"
        izz="0.000021370"/>
    </inertial>
  </link>

  <joint name="upper_right_wheel_shaft_joint" type="fixed">
    <origin xyz="0.150 -0.108 0.0" rpy="${PI} 0 0" />
    <parent link="base_link"/>
    <child link="upper_right_wheel_shaft" />
  </joint>

  <link name="upper_right_wheel_shaft">
    <visual>
      <origin xyz="0 0 0" rpy="0 0 0" />
      <geometry>
        <mesh filename="package://nexus_4wd_mecanum_description/meshes/wheel_shaft.STL" scale="0.001 0.001 0.001"/>
      </geometry>
      <material name="black" />
    </visual>
    <collision>
      <origin xyz="0 0 0"/>
      <geometry>
        <mesh filename="package://nexus_4wd_mecanum_description/meshes/wheel_shaft.STL" scale="0.001 0.001 0.001"/>
      </geometry>
    </collision>
    <inertial>
      <origin xyz="0 0.01221 0" rpy="0 0 0"/>
      <mass value="0.055"/>
      <inertia
        ixx="0.000021370" ixy="0" ixz="0"
        iyy="0.000009966" iyz="0"
        izz="0.000021370"/>
    </inertial>
  </link>

  <joint name="lower_right_wheel_shaft_joint" type="fixed">
    <origin xyz="-0.150 -0.108 0.0" rpy="${PI} 0 0" />
    <parent link="base_link"/>
    <child link="lower_right_wheel_shaft" />
  </joint>

  <link name="lower_right_wheel_shaft">
    <visual>
      <origin xyz="0 0 0" rpy="0 0 0" />
      <geometry>
        <mesh filename="package://nexus_4wd_mecanum_description/meshes/wheel_shaft.STL" scale="0.001 0.001 0.001"/>
      </geometry>
      <material name="black" />
    </visual>
    <collision>
      <origin xyz="0 0 0"/>
      <geometry>
        <mesh filename="package://nexus_4wd_mecanum_description/meshes/wheel_shaft.STL" scale="0.001 0.001 0.001"/>
      </geometry>
    </collision>
    <inertial>
      <origin xyz="0 0.01221 0" rpy="0 0 0"/>
      <mass value="0.055"/>
      <inertia
        ixx="0.000021370" ixy="0" ixz="0"
        iyy="0.000009966" iyz="0"
        izz="0.000021370"/>
    </inertial>
  </link>

  <joint name="upper_left_wheel_joint" type="continuous">
    <origin xyz="0 0.042 0" rpy="0 0 0" />
    <parent link="upper_left_wheel_shaft"/>
    <child link="upper_left_wheel" />
    <axis xyz="0 1 0"/>
  </joint>
  
  <link name="upper_left_wheel">
    <visual>
      <origin xyz="0 0 0" rpy="0 0 0" />
      <geometry>
        <mesh filename="package://nexus_4wd_mecanum_description/meshes/mecanum_wheel_left.STL" scale="0.001 0.001 0.001"/>
      </geometry>
      <material name="light_grey" />
    </visual>
    <collision>
      <origin xyz="0 0 0" rpy="${PI/2} 0 0"/>
      <geometry>
        <cylinder radius="${wheel_radius}" length="${wheel_width}"/>
      </geometry>
    </collision>
    <inertial>
      <origin xyz="0.0 0.0 0.0" rpy="0 0 0"/>
      <mass value="0.3844"/>
      <!-- Inertia based on cylinder -->
      <inertia
        ixx="0.000324824" ixy="0" ixz="0"
        iyy="0.000480000" iyz="0"
        izz="0.000324824"/>
    </inertial>
  </link>

  <joint name="lower_left_wheel_joint" type="continuous">
    <origin xyz="0 0.042 0" rpy="0 0 0" />
    <parent link="lower_left_wheel_shaft"/>
    <child link="lower_left_wheel" />
    <axis xyz="0 1 0"/>
  </joint>

  <link name="lower_left_wheel">
    <visual>
      <origin xyz="0 0 0" rpy="0 0 0" />
      <geometry>
        <mesh filename="package://nexus_4wd_mecanum_description/meshes/mecanum_wheel_right.STL" scale="0.001 0.001 0.001"/>
      </geometry>
      <material name="light_grey" />
    </visual>
    <collision>
      <origin xyz="0 0 0" rpy="${PI/2} 0 0"/>
      <geometry>
        <cylinder radius="${wheel_radius}" length="${wheel_width}"/>
      </geometry>
    </collision>
    <inertial>
      <origin xyz="0.0 0.0 0.0" rpy="0 0 0"/>
      <mass value="0.3844"/>
      <!-- Inertia based on cylinder -->
      <inertia
        ixx="0.000324824" ixy="0" ixz="0"
        iyy="0.000480000" iyz="0"
        izz="0.000324824"/>
    </inertial>
  </link>

  <joint name="upper_right_wheel_joint" type="continuous">
    <origin xyz="0 0.042 0" rpy="0 0 0" />
    <parent link="upper_right_wheel_shaft"/>
    <child link="upper_right_wheel" />
    <axis xyz="0 1 0"/>
  </joint>

  <link name="upper_right_wheel">
    <visual>
      <origin xyz="0 0 0" rpy="0 0 0" />
      <geometry>
        <mesh filename="package://nexus_4wd_mecanum_description/meshes/mecanum_wheel_right.STL" scale="0.001 0.001 0.001"/>
      </geometry>
      <material name="light_grey" />
    </visual>
    <collision>
      <origin xyz="0 0 0" rpy="${PI/2} 0 0"/>
      <geometry>
        <cylinder radius="${wheel_radius}" length="${wheel_width}"/>
      </geometry>
    </collision>
    <inertial>
      <origin xyz="0.0 0.0 0.0" rpy="0 0 0"/>
      <mass value="0.3844"/>
      <!-- Inertia based on cylinder -->
      <inertia
        ixx="0.000324824" ixy="0" ixz="0"
        iyy="0.000480000" iyz="0"
        izz="0.000324824"/>
    </inertial>
  </link>
  
  <joint name="lower_right_wheel_joint" type="continuous">
    <origin xyz="0 0.042 0" rpy="0 0 0" />
    <parent link="lower_right_wheel_shaft"/>
    <child link="lower_right_wheel" />
    <axis xyz="0 1 0"/>
  </joint>

  <link name="lower_right_wheel">
    <visual>
      <origin xyz="0 0 0" rpy="0 0 0" />
      <geometry>
        <mesh filename="package://nexus_4wd_mecanum_description/meshes/mecanum_wheel_left.STL" scale="0.001 0.001 0.001"/>
      </geometry>
      <material name="light_grey" />
    </visual>
    <collision>
      <origin xyz="0 0 0" rpy="${PI/2} 0 0"/>
      <geometry>
        <cylinder radius="${wheel_radius}" length="${wheel_width}"/>
      </geometry>
    </collision>
    <inertial>
      <origin xyz="0.0 0.0 0.0" rpy="0 0 0"/>
      <mass value="0.3844"/>
      <!-- Inertia based on cylinder -->
      <inertia
        ixx="0.000324824" ixy="0" ixz="0"
        iyy="0.000480000" iyz="0"
        izz="0.000324824"/>
    </inertial>
  </link>

  <joint name="left_sensor_joint" type="fixed">
    <origin xyz="0 0.108 0.010" rpy="0 0 ${PI/2}" />
    <parent link="base_link"/>
    <child link="left_sensor" />
  </joint>

  <link name="left_sensor">
    <visual>
      <origin xyz="0 0 0" rpy="${PI/2} 0 0" />
      <geometry>
        <mesh filename="package://nexus_4wd_mecanum_description/meshes/urm04.STL" scale="0.001 0.001 0.001"/>
      </geometry>
      <material name="black" />
    </visual>
  </link>

  <joint name="front_sensor_joint" type="fixed">
    <origin xyz="0.205 0 0.010" rpy="0 0 0" />
    <parent link="base_link"/>
    <child link="front_sensor" />
  </joint>

  <link name="front_sensor">
    <visual>
      <origin xyz="0 0 0" rpy="${PI/2} 0 0" />
      <geometry>
        <mesh filename="package://nexus_4wd_mecanum_description/meshes/urm04.STL" scale="0.001 0.001 0.001"/>
      </geometry>
      <material name="black" />
    </visual>
  </link>

  <joint name="right_sensor_joint" type="fixed">
    <origin xyz="0 -0.108 0.010" rpy="0 0 ${-PI/2}" />
    <parent link="base_link"/>
    <child link="right_sensor" />
  </joint>

  <link name="right_sensor">
    <visual>
      <origin xyz="0 0 0" rpy="${PI/2} 0 0" />
      <geometry>
        <mesh filename="package://nexus_4wd_mecanum_description/meshes/urm04.STL" scale="0.001 0.001 0.001"/>
      </geometry>
      <material name="black" />
    </visual>
  </link>

  <joint name="rear_sensor_joint" type="fixed">
    <origin xyz="-0.201 0 0.010" rpy="0 0 ${PI}" />
    <parent link="base_link"/>
    <child link="rear_sensor" />
  </joint>

  <link name="rear_sensor">
    <visual>
      <origin xyz="0 0 0" rpy="${PI/2} 0 0" />
      <geometry>
        <mesh filename="package://nexus_4wd_mecanum_description/meshes/urm04.STL" scale="0.001 0.001 0.001"/>
      </geometry>
      <material name="black" />
    </visual>
  </link>

  <!-- Include controller plugin for Gazebo -->
  <xacro:include filename="$(find nexus_4wd_mecanum_description)/urdf/nexus_4wd_mecanum.gazebo" />

  <!-- Include URM04 ultrasonic range finders -->
  <xacro:include filename="$(find nexus_4wd_mecanum_description)/urdf/urm04_sensor.xacro"/>
  <!-- front sensor -->
  <xacro:urm04_sensor frame_name="front_sensor" ros_topic="front_sensor" update_rate="10" min_range="0.04" max_range="2.5" horizontal_field_of_view="1.04" vertical_field_of_view="0.04" ray_count="2" />
  <!-- left sensor -->
  <xacro:urm04_sensor frame_name="left_sensor" ros_topic="left_sensor" update_rate="10" min_range="0.04" max_range="2.5" horizontal_field_of_view="1.04" vertical_field_of_view="0.04" ray_count="2" />
  <!-- right sensor -->
  <xacro:urm04_sensor frame_name="right_sensor" ros_topic="right_sensor" update_rate="10" min_range="0.04" max_range="2.5" horizontal_field_of_view="1.04" vertical_field_of_view="0.04" ray_count="2" />
  <!-- rear sensor -->
  <xacro:urm04_sensor frame_name="rear_sensor" ros_topic="rear_sensor" update_rate="10" min_range="0.04" max_range="2.5" horizontal_field_of_view="1.04" vertical_field_of_view="0.04" ray_count="2" />



 

<joint name="laser_joint" type="fixed">
        <parent link="base_link"/>
        <child link="laser_frame"/>
        <origin xyz="0.1 0 0.055" rpy="0 0 0"/>
</joint>

<link name="laser_frame">
    <visual>
        <geometry>
            <cylinder radius="0.05" length="0.04"/>
        </geometry>
        <material name="red"/>
    </visual>
    <collision>
        <geometry>
            <cylinder radius="0.05" length="0.04"/>
        </geometry>
    </collision>
    <!-- <xacro:inertial_cylinder mass="0.1" length="0.04" radius="0.05">
        <origin xyz="0 0 0" rpy="0 0 0"/>
    </xacro:inertial_cylinder> -->
</link>


  <!-- hokuyo -->
<gazebo reference="laser_frame">
    <sensor type="ray" name="head_hokuyo_sensor">
      <pose>0 0 0 0 0 0</pose>
      <visualize>false</visualize>
      <update_rate>40</update_rate>
      <ray>
        <scan>
          <horizontal>
            <samples>720</samples>
            <resolution>1</resolution>
            <min_angle>-${PI}</min_angle>
            <max_angle>${PI}</max_angle>
          </horizontal>
        </scan>
        <range>
          <min>0.10</min>
          <max>15.0</max>
          <resolution>0.01</resolution>
        </range>
        <noise>
          <type>gaussian</type>
          <!-- Noise parameters based on published spec for Hokuyo laser
               achieving "+-30mm" accuracy at range < 10m.  A mean of 0.0m and
               stddev of 0.01m will put 99.7% of samples within 0.03m of the true
               reading. -->
          <mean>0.0</mean>
          <stddev>0.01</stddev>
        </noise>
      </ray>
      <plugin name="gazebo_ros_head_hokuyo_controller" filename="libgazebo_ros_laser.so">
        <topicName>/laser/scan</topicName>
        <frameName>laser_frame</frameName>
      </plugin>
    </sensor>
</gazebo>



</robot>


